<?xml version="1.0" ?>
<mujoco model="assemblyDerived_v17">
  <default>
    <mesh scale="0.001 0.001 0.001"/>
    <geom rgba="0.5 0.7 1.0 1" contype="0" conaffinity="0"/>
    <joint damping="0.005" range="-1.5 1.5"/>
    <position kp="0.25" forcelimited="true" forcerange="-0.2 0.2"/>
  </default>
  <asset>
    <mesh file="meshes/derivedBody_v1_1.stl" name="derivedBody_v1_1_mesh"/>
    <mesh file="meshes/servo_v9_2.stl" name="servo_v9_2_mesh"/>
    <mesh file="meshes/derivedLeg_v1(Mirror)_1.stl" name="derivedLeg_v1(Mirror)_1_mesh"/>
    <mesh file="meshes/servo_v9_4.stl" name="servo_v9_4_mesh"/>
    <mesh file="meshes/derivedLeg_v1(Mirror)_2.stl" name="derivedLeg_v1(Mirror)_2_mesh"/>
    <mesh file="meshes/servo_v9_6.stl" name="servo_v9_6_mesh"/>
    <mesh file="meshes/derivedFoot_v2(Mirror)_1.stl" name="derivedFoot_v2(Mirror)_1_mesh"/>
    <mesh file="meshes/servo_v9_1.stl" name="servo_v9_1_mesh"/>
    <mesh file="meshes/derivedLeg_v2_1.stl" name="derivedLeg_v2_1_mesh"/>
    <mesh file="meshes/servo_v9_3.stl" name="servo_v9_3_mesh"/>
    <mesh file="meshes/derivedLeg_v2_2.stl" name="derivedLeg_v2_2_mesh"/>
    <mesh file="meshes/servo_v9_5.stl" name="servo_v9_5_mesh"/>
    <mesh file="meshes/derivedFoot_v2_1.stl" name="derivedFoot_v2_1_mesh"/>
  </asset>
  <actuator>
    <position name="derivedLeg_v1(Mirror)_1Revolute_4" joint="derivedLeg_v1(Mirror)_1Revolute_4"/>
    <position name="derivedLeg_v1(Mirror)_2Revolute_8" joint="derivedLeg_v1(Mirror)_2Revolute_8"/>
    <position name="derivedFoot_v2(Mirror)_1Revolute_12" joint="derivedFoot_v2(Mirror)_1Revolute_12"/>
    <position name="derivedLeg_v2_1Revolute_3" joint="derivedLeg_v2_1Revolute_3"/>
    <position name="derivedLeg_v2_2Revolute_7" joint="derivedLeg_v2_2Revolute_7"/>
    <position name="derivedFoot_v2_1Revolute_11" joint="derivedFoot_v2_1Revolute_11"/>
  </actuator>

  <sensor>
    <gyro name="gyro" site="imu_site"/>
    <accelerometer name="accel" site="imu_site"/>
    <framequat name="orientation" objtype="site" objname="imu_site"/>
  </sensor>

  <worldbody>
    <geom name="floor" size="0 0 .05" type="plane" condim="3" rgba="0.9 0.9 0.9 1" contype="1" conaffinity="1"/>
    <light mode="targetbodycom" target="body" diffuse=".8 .8 .8" specular="0.3 0.3 0.3" pos="0 -6 4" cutoff="30"/>
    <body name="body" pos="0 0 0.149091">
      <freejoint name="root"/>
      <site name="imu_site" pos="0 0.0085 0.097" size="0.001" rgba="1 0 0 1"/>
      <geom density="248" type="mesh" mesh="derivedBody_v1_1_mesh"/>
      <body name="servo_v9_2">
        <geom mass="0.013" type="mesh" mesh="servo_v9_2_mesh"/>
        <body name="derivedLeg_v1(Mirror)_1">
          <joint axis="1 0 0" name="derivedLeg_v1(Mirror)_1Revolute_4" type="hinge" pos="0.0570 0.0100 0.0109"/>
          <geom density="248" type="mesh" mesh="derivedLeg_v1(Mirror)_1_mesh"/>
          <body name="servo_v9_4">
            <geom mass="0.013" type="mesh" mesh="servo_v9_4_mesh"/>
            <body name="derivedLeg_v1(Mirror)_2">
              <joint axis="1 0 0" name="derivedLeg_v1(Mirror)_2Revolute_8" type="hinge" pos="0.0570 0.0100 -0.0591"/>
              <geom density="248" type="mesh" mesh="derivedLeg_v1(Mirror)_2_mesh"/>
              <body name="servo_v9_6">
                <geom mass="0.013" type="mesh" mesh="servo_v9_6_mesh"/>
                <body name="derivedFoot_v2(Mirror)_1">
                  <joint axis="1 0 0" name="derivedFoot_v2(Mirror)_1Revolute_12" type="hinge" pos="0.0570 0.0100 -0.1291"/>
                  <geom density="248" type="mesh" mesh="derivedFoot_v2(Mirror)_1_mesh"/>
                  <geom type="box"  pos="0.041 0.0075 -0.147591" size="0.021 0.0335 0.0015" rgba="1 0 0 0.5" contype="1" conaffinity="1" density="248" friction="1.5 0.1 0.001" solref="0.02 1"/>
                </body>
              </body>
            </body>
          </body>
        </body>
      </body>
      <body name="servo_v9_1">
        <geom mass="0.013" type="mesh" mesh="servo_v9_1_mesh"/>
        <body name="derivedLeg_v2_1">
          <joint axis="1 0 0" name="derivedLeg_v2_1Revolute_3" type="hinge" pos="-0.0570 0.0100 0.0109"/>
          <geom density="248" type="mesh" mesh="derivedLeg_v2_1_mesh"/>
          <body name="servo_v9_3">
            <geom mass="0.013" type="mesh" mesh="servo_v9_3_mesh"/>
            <body name="derivedLeg_v2_2">
              <joint axis="1 0 0" name="derivedLeg_v2_2Revolute_7" type="hinge" pos="-0.0570 0.0100 -0.0591"/>
              <geom density="248" type="mesh" mesh="derivedLeg_v2_2_mesh"/>
              <body name="servo_v9_5">
                <geom mass="0.013" type="mesh" mesh="servo_v9_5_mesh"/>
                <body name="derivedFoot_v2_1">
                  <joint axis="1 0 0" name="derivedFoot_v2_1Revolute_11" type="hinge" pos="-0.0570 0.0100 -0.1291"/>
                  <geom density="248" type="mesh" mesh="derivedFoot_v2_1_mesh"/>
                  <geom type="box" pos="-0.041 0.0075 -0.147591" size="0.021 0.0335 0.0015" rgba="1 0 0 0.5" contype="1" conaffinity="1" density="248" friction="1.5 0.1 0.001" solref="0.02 1"/>
                </body>
              </body>
            </body>
          </body>
        </body>
      </body>
    </body>
    <camera name="track" mode="trackcom" pos="0 -2.1 0.5" xyaxes="1 0 0 0 0.2 1" target="body"/>
  </worldbody>
</mujoco>
