<?xml version="1.0" ?>
<mujoco model="assemblyDerived_v3">
  <default>
    <mesh scale="0.001 0.001 0.001"/>
    <geom rgba="0.5 0.7 1.0 1"/>
    <joint damping="1"/>
    <position kp="14"/>
  </default>
  <asset>
    <mesh file="meshes/derivedBody_v1_1.stl" name="derivedBody_v1_1_mesh"/>
    <mesh file="meshes/servo_v9_1.stl" name="servo_v9_1_mesh"/>
    <mesh file="meshes/derivedLeg_v1_1.stl" name="derivedLeg_v1_1_mesh"/>
    <mesh file="meshes/servo_v9_2.stl" name="servo_v9_2_mesh"/>
    <mesh file="meshes/derivedLeg_v1(Mirror)_1.stl" name="derivedLeg_v1(Mirror)_1_mesh"/>
  </asset>
  <actuator>
    <position name="derivedLeg_v1_1Revolute_3" joint="derivedLeg_v1_1Revolute_3"/>
    <position name="derivedLeg_v1(Mirror)_1Revolute_4" joint="derivedLeg_v1(Mirror)_1Revolute_4"/>
  </actuator>
  <worldbody>
    <geom type="plane" size="1 1 0.1" rgba="0.9 0.9 0.9 1"/>
    <light mode="targetbodycom" target="body" diffuse=".8 .8 .8" specular="0.3 0.3 0.3" pos="0 -6 4" cutoff="30"/>
    <body name="body" pos="0 0 .17355">
      <freejoint name="root"/>
      <geom type="mesh" mesh="derivedBody_v1_1_mesh"/>
      <body name="servo_v9_1">
        <geom type="mesh" mesh="servo_v9_1_mesh"/>
        <body name="derivedLeg_v1_1">
          <joint axis="1 0 0" name="derivedLeg_v1_1Revolute_3" type="hinge" pos="0.0751 0.0000 -0.0222"/>
          <geom type="mesh" mesh="derivedLeg_v1_1_mesh"/>
        </body>
      </body>
      <body name="servo_v9_2">
        <geom type="mesh" mesh="servo_v9_2_mesh"/>
        <body name="derivedLeg_v1(Mirror)_1">
          <joint axis="1 0 0" name="derivedLeg_v1(Mirror)_1Revolute_4" type="hinge" pos="0.1549 0.0000 -0.0222"/>
          <geom type="mesh" mesh="derivedLeg_v1(Mirror)_1_mesh"/>
        </body>
      </body>
    </body>
  </worldbody>
</mujoco>
