<?xml version="1.0" ?>
<mujoco model="doubleImport_v8">
  <default>
    <mesh scale="0.001 0.001 0.001"/>
    <geom rgba="0.5 0.7 1.0 1"/>
    <joint damping="1"/>
    <position kp="14"/>
  </default>
  <asset>
    <mesh file="meshes/robotImported_v8_1.stl" name="robotImported_v8_1_mesh"/>
    <mesh file="meshes/robotImported_v8_1+left-leg_v15_1+servo_v3_1.stl" name="robotImported_v8_1+left-leg_v15_1+servo_v3_1_mesh"/>
    <mesh file="meshes/robotImported_v8_1+left-leg_v15_1+Motor_mount_v10_1+mount_1.stl" name="robotImported_v8_1+left-leg_v15_1+Motor_mount_v10_1+mount_1_mesh"/>
    <mesh file="meshes/robotImported_v8_1+left-leg_v15_1+servo_v3_2.stl" name="robotImported_v8_1+left-leg_v15_1+servo_v3_2_mesh"/>
    <mesh file="meshes/robotImported_v8_1+left-leg_v15_1+Motor_mount_v10_2+mount_1.stl" name="robotImported_v8_1+left-leg_v15_1+Motor_mount_v10_2+mount_1_mesh"/>
    <mesh file="meshes/robotImported_v8_1+left-leg_v15_1+servo_v3_3.stl" name="robotImported_v8_1+left-leg_v15_1+servo_v3_3_mesh"/>
    <mesh file="meshes/robotImported_v8_1+left-leg_v15_1+LegMount_v7_1.stl" name="robotImported_v8_1+left-leg_v15_1+LegMount_v7_1_mesh"/>
    <mesh file="meshes/robotImported_v8_1+left-leg_v15_1+servo_v3_4.stl" name="robotImported_v8_1+left-leg_v15_1+servo_v3_4_mesh"/>
    <mesh file="meshes/robotImported_v8_1+left-leg_v15_1+lowerLeg_v4_1.stl" name="robotImported_v8_1+left-leg_v15_1+lowerLeg_v4_1_mesh"/>
    <mesh file="meshes/robotImported_v8_1+left-leg_v15_1+servo_v3_5.stl" name="robotImported_v8_1+left-leg_v15_1+servo_v3_5_mesh"/>
    <mesh file="meshes/robotImported_v8_1+left-leg_v15_1+foot_v7_1.stl" name="robotImported_v8_1+left-leg_v15_1+foot_v7_1_mesh"/>
    <mesh file="meshes/robotImported_v8_1+rightLeg_v11_1+left-leg_v10(Mirror)_1+servo_v2(Mirror)_1.stl" name="robotImported_v8_1+rightLeg_v11_1+left-leg_v10(Mirror)_1+servo_v2(Mirror)_1_mesh"/>
    <mesh file="meshes/robotImported_v8_1+rightLeg_v11_1+left-leg_v10(Mirror)_1+Motor_mount_v7(Mirror)_1+mount(Mirror)_1.stl" name="robotImported_v8_1+rightLeg_v11_1+left-leg_v10(Mirror)_1+Motor_mount_v7(Mirror)_1+mount(Mirror)_1_mesh"/>
    <mesh file="meshes/robotImported_v8_1+rightLeg_v11_1+left-leg_v10(Mirror)_1+servo_v2(Mirror)_2.stl" name="robotImported_v8_1+rightLeg_v11_1+left-leg_v10(Mirror)_1+servo_v2(Mirror)_2_mesh"/>
    <mesh file="meshes/robotImported_v8_1+rightLeg_v11_1+left-leg_v10(Mirror)_1+Motor_mount_v7(Mirror)_2+mount(Mirror)_1.stl" name="robotImported_v8_1+rightLeg_v11_1+left-leg_v10(Mirror)_1+Motor_mount_v7(Mirror)_2+mount(Mirror)_1_mesh"/>
    <mesh file="meshes/robotImported_v8_1+rightLeg_v11_1+left-leg_v10(Mirror)_1+servo_v2(Mirror)_3.stl" name="robotImported_v8_1+rightLeg_v11_1+left-leg_v10(Mirror)_1+servo_v2(Mirror)_3_mesh"/>
    <mesh file="meshes/robotImported_v8_1+rightLeg_v11_1+left-leg_v10(Mirror)_1+LegMount_v7(Mirror)_1.stl" name="robotImported_v8_1+rightLeg_v11_1+left-leg_v10(Mirror)_1+LegMount_v7(Mirror)_1_mesh"/>
    <mesh file="meshes/robotImported_v8_1+rightLeg_v11_1+left-leg_v10(Mirror)_1+servo_v2(Mirror)_4.stl" name="robotImported_v8_1+rightLeg_v11_1+left-leg_v10(Mirror)_1+servo_v2(Mirror)_4_mesh"/>
    <mesh file="meshes/robotImported_v8_1+rightLeg_v11_1+left-leg_v10(Mirror)_1+lowerLeg_v4(Mirror)_1.stl" name="robotImported_v8_1+rightLeg_v11_1+left-leg_v10(Mirror)_1+lowerLeg_v4(Mirror)_1_mesh"/>
    <mesh file="meshes/robotImported_v8_1+rightLeg_v11_1+left-leg_v10(Mirror)_1+servo_v2(Mirror)_5.stl" name="robotImported_v8_1+rightLeg_v11_1+left-leg_v10(Mirror)_1+servo_v2(Mirror)_5_mesh"/>
    <mesh file="meshes/robotImported_v8_1+rightLeg_v11_1+left-leg_v10(Mirror)_1+foot_v7(Mirror)_1.stl" name="robotImported_v8_1+rightLeg_v11_1+left-leg_v10(Mirror)_1+foot_v7(Mirror)_1_mesh"/>
  </asset>
  <actuator>
    <position name="robotImported_v8_1+left-leg_v15_1+Motor_mount_v10_1+mount_1Revolute_1" joint="robotImported_v8_1+left-leg_v15_1+Motor_mount_v10_1+mount_1Revolute_1"/>
    <position name="robotImported_v8_1+left-leg_v15_1+Motor_mount_v10_2+mount_1Revolute_3" joint="robotImported_v8_1+left-leg_v15_1+Motor_mount_v10_2+mount_1Revolute_3"/>
    <position name="robotImported_v8_1+left-leg_v15_1+LegMount_v7_1Revolute_5" joint="robotImported_v8_1+left-leg_v15_1+LegMount_v7_1Revolute_5"/>
    <position name="robotImported_v8_1+left-leg_v15_1+lowerLeg_v4_1Revolute_7" joint="robotImported_v8_1+left-leg_v15_1+lowerLeg_v4_1Revolute_7"/>
    <position name="robotImported_v8_1+left-leg_v15_1+foot_v7_1Revolute_9" joint="robotImported_v8_1+left-leg_v15_1+foot_v7_1Revolute_9"/>
    <position name="robotImported_v8_1+rightLeg_v11_1+left-leg_v10(Mirror)_1+Motor_mount_v7(Mirror)_1+mount(Mirror)_1Revolute_1" joint="robotImported_v8_1+rightLeg_v11_1+left-leg_v10(Mirror)_1+Motor_mount_v7(Mirror)_1+mount(Mirror)_1Revolute_1"/>
    <position name="robotImported_v8_1+rightLeg_v11_1+left-leg_v10(Mirror)_1+Motor_mount_v7(Mirror)_2+mount(Mirror)_1Revolute_3" joint="robotImported_v8_1+rightLeg_v11_1+left-leg_v10(Mirror)_1+Motor_mount_v7(Mirror)_2+mount(Mirror)_1Revolute_3"/>
    <position name="robotImported_v8_1+rightLeg_v11_1+left-leg_v10(Mirror)_1+LegMount_v7(Mirror)_1Revolute_5" joint="robotImported_v8_1+rightLeg_v11_1+left-leg_v10(Mirror)_1+LegMount_v7(Mirror)_1Revolute_5"/>
    <position name="robotImported_v8_1+rightLeg_v11_1+left-leg_v10(Mirror)_1+lowerLeg_v4(Mirror)_1Revolute_7" joint="robotImported_v8_1+rightLeg_v11_1+left-leg_v10(Mirror)_1+lowerLeg_v4(Mirror)_1Revolute_7"/>
    <position name="robotImported_v8_1+rightLeg_v11_1+left-leg_v10(Mirror)_1+foot_v7(Mirror)_1Revolute_9" joint="robotImported_v8_1+rightLeg_v11_1+left-leg_v10(Mirror)_1+foot_v7(Mirror)_1Revolute_9"/>
  </actuator>
  <worldbody>
    <geom type="plane" size="1 1 0.1" rgba="0.9 0.9 0.9 1"/>
    <light mode="targetbodycom" target="body" diffuse=".8 .8 .8" specular="0.3 0.3 0.3" pos="0 -6 4" cutoff="30"/>
    <body name="body" pos="0 0 .17355">
      <freejoint name="root"/>
      <geom type="mesh" mesh="robotImported_v8_1_mesh"/>
      <body name="robotImported_v8_1+left-leg_v15_1+servo_v3_1">
        <geom type="mesh" mesh="robotImported_v8_1+left-leg_v15_1+servo_v3_1_mesh"/>
        <body name="robotImported_v8_1+left-leg_v15_1+Motor_mount_v10_1+mount_1">
          <joint axis="1 0 0" name="robotImported_v8_1+left-leg_v15_1+Motor_mount_v10_1+mount_1Revolute_1" type="hinge" pos="-0.0600 0.0120 0.0290"/>
          <geom type="mesh" mesh="robotImported_v8_1+left-leg_v15_1+Motor_mount_v10_1+mount_1_mesh"/>
          <body name="robotImported_v8_1+left-leg_v15_1+servo_v3_2">
            <geom type="mesh" mesh="robotImported_v8_1+left-leg_v15_1+servo_v3_2_mesh"/>
            <body name="robotImported_v8_1+left-leg_v15_1+Motor_mount_v10_2+mount_1">
              <joint axis="1 0 0" name="robotImported_v8_1+left-leg_v15_1+Motor_mount_v10_2+mount_1Revolute_3" type="hinge" pos="-0.0644 0.0324 0.0211"/>
              <geom type="mesh" mesh="robotImported_v8_1+left-leg_v15_1+Motor_mount_v10_2+mount_1_mesh"/>
              <body name="robotImported_v8_1+left-leg_v15_1+servo_v3_3">
                <geom type="mesh" mesh="robotImported_v8_1+left-leg_v15_1+servo_v3_3_mesh"/>
                <body name="robotImported_v8_1+left-leg_v15_1+LegMount_v7_1">
                  <joint axis="1 0 0" name="robotImported_v8_1+left-leg_v15_1+LegMount_v7_1Revolute_5" type="hinge" pos="-0.0848 0.0403 0.0088"/>
                  <geom type="mesh" mesh="robotImported_v8_1+left-leg_v15_1+LegMount_v7_1_mesh"/>
                  <body name="robotImported_v8_1+left-leg_v15_1+servo_v3_4">
                    <geom type="mesh" mesh="robotImported_v8_1+left-leg_v15_1+servo_v3_4_mesh"/>
                    <body name="robotImported_v8_1+left-leg_v15_1+lowerLeg_v4_1">
                      <joint axis="1 0 0" name="robotImported_v8_1+left-leg_v15_1+lowerLeg_v4_1Revolute_7" type="hinge" pos="-0.0989 0.0440 -0.0554"/>
                      <geom type="mesh" mesh="robotImported_v8_1+left-leg_v15_1+lowerLeg_v4_1_mesh"/>
                      <body name="robotImported_v8_1+left-leg_v15_1+servo_v3_5">
                        <geom type="mesh" mesh="robotImported_v8_1+left-leg_v15_1+servo_v3_5_mesh"/>
                        <body name="robotImported_v8_1+left-leg_v15_1+foot_v7_1">
                          <joint axis="1 0 0" name="robotImported_v8_1+left-leg_v15_1+foot_v7_1Revolute_9" type="hinge" pos="-0.1130 0.0478 -0.0896"/>
                          <geom type="mesh" mesh="robotImported_v8_1+left-leg_v15_1+foot_v7_1_mesh"/>
                        </body>
                      </body>
                    </body>
                  </body>
                </body>
              </body>
            </body>
          </body>
        </body>
      </body>
      <body name="robotImported_v8_1+rightLeg_v11_1+left-leg_v10(Mirror)_1+servo_v2(Mirror)_1">
        <geom type="mesh" mesh="robotImported_v8_1+rightLeg_v11_1+left-leg_v10(Mirror)_1+servo_v2(Mirror)_1_mesh"/>
        <body name="robotImported_v8_1+rightLeg_v11_1+left-leg_v10(Mirror)_1+Motor_mount_v7(Mirror)_1+mount(Mirror)_1">
          <joint axis="1 0 0" name="robotImported_v8_1+rightLeg_v11_1+left-leg_v10(Mirror)_1+Motor_mount_v7(Mirror)_1+mount(Mirror)_1Revolute_1" type="hinge" pos="0.0600 0.0120 0.0290"/>
          <geom type="mesh" mesh="robotImported_v8_1+rightLeg_v11_1+left-leg_v10(Mirror)_1+Motor_mount_v7(Mirror)_1+mount(Mirror)_1_mesh"/>
          <body name="robotImported_v8_1+rightLeg_v11_1+left-leg_v10(Mirror)_1+servo_v2(Mirror)_2">
            <geom type="mesh" mesh="robotImported_v8_1+rightLeg_v11_1+left-leg_v10(Mirror)_1+servo_v2(Mirror)_2_mesh"/>
            <body name="robotImported_v8_1+rightLeg_v11_1+left-leg_v10(Mirror)_1+Motor_mount_v7(Mirror)_2+mount(Mirror)_1">
              <joint axis="1 0 0" name="robotImported_v8_1+rightLeg_v11_1+left-leg_v10(Mirror)_1+Motor_mount_v7(Mirror)_2+mount(Mirror)_1Revolute_3" type="hinge" pos="0.0644 0.0324 0.0209"/>
              <geom type="mesh" mesh="robotImported_v8_1+rightLeg_v11_1+left-leg_v10(Mirror)_1+Motor_mount_v7(Mirror)_2+mount(Mirror)_1_mesh"/>
              <body name="robotImported_v8_1+rightLeg_v11_1+left-leg_v10(Mirror)_1+servo_v2(Mirror)_3">
                <geom type="mesh" mesh="robotImported_v8_1+rightLeg_v11_1+left-leg_v10(Mirror)_1+servo_v2(Mirror)_3_mesh"/>
                <body name="robotImported_v8_1+rightLeg_v11_1+left-leg_v10(Mirror)_1+LegMount_v7(Mirror)_1">
                  <joint axis="1 0 0" name="robotImported_v8_1+rightLeg_v11_1+left-leg_v10(Mirror)_1+LegMount_v7(Mirror)_1Revolute_5" type="hinge" pos="0.0848 0.0405 0.0086"/>
                  <geom type="mesh" mesh="robotImported_v8_1+rightLeg_v11_1+left-leg_v10(Mirror)_1+LegMount_v7(Mirror)_1_mesh"/>
                  <body name="robotImported_v8_1+rightLeg_v11_1+left-leg_v10(Mirror)_1+servo_v2(Mirror)_4">
                    <geom type="mesh" mesh="robotImported_v8_1+rightLeg_v11_1+left-leg_v10(Mirror)_1+servo_v2(Mirror)_4_mesh"/>
                    <body name="robotImported_v8_1+rightLeg_v11_1+left-leg_v10(Mirror)_1+lowerLeg_v4(Mirror)_1">
                      <joint axis="1 0 0" name="robotImported_v8_1+rightLeg_v11_1+left-leg_v10(Mirror)_1+lowerLeg_v4(Mirror)_1Revolute_7" type="hinge" pos="0.0989 0.0444 -0.0558"/>
                      <geom type="mesh" mesh="robotImported_v8_1+rightLeg_v11_1+left-leg_v10(Mirror)_1+lowerLeg_v4(Mirror)_1_mesh"/>
                      <body name="robotImported_v8_1+rightLeg_v11_1+left-leg_v10(Mirror)_1+servo_v2(Mirror)_5">
                        <geom type="mesh" mesh="robotImported_v8_1+rightLeg_v11_1+left-leg_v10(Mirror)_1+servo_v2(Mirror)_5_mesh"/>
                        <body name="robotImported_v8_1+rightLeg_v11_1+left-leg_v10(Mirror)_1+foot_v7(Mirror)_1">
                          <joint axis="1 0 0" name="robotImported_v8_1+rightLeg_v11_1+left-leg_v10(Mirror)_1+foot_v7(Mirror)_1Revolute_9" type="hinge" pos="0.1130 0.0484 -0.0902"/>
                          <geom type="mesh" mesh="robotImported_v8_1+rightLeg_v11_1+left-leg_v10(Mirror)_1+foot_v7(Mirror)_1_mesh"/>
                        </body>
                      </body>
                    </body>
                  </body>
                </body>
              </body>
            </body>
          </body>
        </body>
      </body>
    </body>
  </worldbody>
</mujoco>
