<?xml version="1.0" ?>
<mujoco model="rickv3_v25">
  <compiler angle="radian"/>

  <default>
    <mesh scale="0.001 0.001 0.001"/>
    <geom rgba="0.5 0.7 1.0 1" contype="0" conaffinity="0"/>
    <joint damping="0.002" range="-1.5 1.5" armature="0.0005"/>
    <position kp="0.5" kv="0.02" forcelimited="true" forcerange="-0.2 0.2" ctrllimited="true" ctrlrange="-1.57 1.57"/>
  </default>
  <asset>
    <mesh file="meshes/Untitled_v8_1.stl" name="Untitled_v8_1_mesh"/>
    <mesh file="meshes/servo_v10_1.stl" name="servo_v10_1_mesh"/>
    <mesh file="meshes/leg2Derived_v5_1.stl" name="leg2Derived_v5_1_mesh"/>
    <mesh file="meshes/servo_v10_2.stl" name="servo_v10_2_mesh"/>
    <mesh file="meshes/leg2Derived_v5_2.stl" name="leg2Derived_v5_2_mesh"/>
    <mesh file="meshes/servo_v10_3.stl" name="servo_v10_3_mesh"/>
    <mesh file="meshes/footDerived_v6_1.stl" name="footDerived_v6_1_mesh"/>
    <mesh file="meshes/servo_v10_6.stl" name="servo_v10_6_mesh"/>
    <mesh file="meshes/legMirrorDerived_v6_1.stl" name="legMirrorDerived_v6_1_mesh"/>
    <mesh file="meshes/servo_v10_4.stl" name="servo_v10_4_mesh"/>
    <mesh file="meshes/legMirrorDerived_v6_2.stl" name="legMirrorDerived_v6_2_mesh"/>
    <mesh file="meshes/servo_v10_5.stl" name="servo_v10_5_mesh"/>
    <mesh file="meshes/foorMirrorDerived_v9_1.stl" name="foorMirrorDerived_v9_1_mesh"/>
  </asset>
  <actuator>
    <position name="leg2Derived_v5_1Revolute_28" joint="leg2Derived_v5_1Revolute_28"/>
    <position name="leg2Derived_v5_2Revolute_30" joint="leg2Derived_v5_2Revolute_30"/>
    <position name="footDerived_v6_1Revolute_32" joint="footDerived_v6_1Revolute_32"/>
    <position name="leftHip" joint="leftHip"/>
    <position name="legMirrorDerived_v6_2Revolute_36" joint="legMirrorDerived_v6_2Revolute_36"/>
    <position name="foorMirrorDerived_v9_1Revolute_38" joint="foorMirrorDerived_v9_1Revolute_38"/>
  </actuator>

  <sensor>
    <gyro name="gyro" site="imu_site"/>
    <accelerometer name="accel" site="imu_site"/>
    <framequat name="orientation" objtype="site" objname="imu_site"/>
  </sensor>

  <worldbody>
    <geom name="floor" size="0 0 .05" type="plane" condim="3" rgba="0.9 0.9 0.9 1" contype="1" conaffinity="1"/>
    <light mode="targetbodycom" target="body" diffuse=".8 .8 .8" specular="0.3 0.3 0.3" pos="0 -6 4" cutoff="30"/>
    <body name="body" pos="0 0 0.111891">
      <freejoint name="root"/>
      <site name="imu_site" pos="0.02 0.0085 0.097" size="0.001" rgba="1 0 0 1"/>
      <geom density="500" type="mesh" mesh="Untitled_v8_1_mesh"/>
      <body name="servo_v10_1">
        <geom mass="0.013" type="mesh" mesh="servo_v10_1_mesh"/>
        <body name="leg2Derived_v5_1">
          <joint axis="1 0 0" name="leg2Derived_v5_1Revolute_28" type="hinge" pos="-0.0370 0.0100 0.0109"/>
          <geom density="500" type="mesh" mesh="leg2Derived_v5_1_mesh"/>
          <body name="servo_v10_2">
            <geom mass="0.013" type="mesh" mesh="servo_v10_2_mesh"/>
            <body name="leg2Derived_v5_2">
              <joint axis="1 0 0" name="leg2Derived_v5_2Revolute_30" type="hinge" pos="-0.0367 0.0100 -0.0365"/>
              <geom density="500" type="mesh" mesh="leg2Derived_v5_2_mesh"/>
              <body name="servo_v10_3">
                <geom mass="0.013" type="mesh" mesh="servo_v10_3_mesh"/>
                <body name="footDerived_v6_1">
                  <joint axis="1 0 0" name="footDerived_v6_1Revolute_32" type="hinge" pos="-0.0367 0.0100 -0.0839"/>
                  <geom density="500" type="mesh" mesh="footDerived_v6_1_mesh" contype="1" conaffinity="1"  friction="1.5 0.1 0.001" solref="0.02 1"/>
                </body>
              </body>
            </body>
          </body>
        </body>
      </body>
      <body name="servo_v10_6">
        <geom mass="0.013" type="mesh" mesh="servo_v10_6_mesh"/>
        <body name="legMirrorDerived_v6_1">
          <joint axis="1 0 0" name="leftHip" type="hinge" pos="-0.0370 0.0100 0.0109"/>
          <geom density="500" type="mesh" mesh="legMirrorDerived_v6_1_mesh"/>
          <body name="servo_v10_4">
            <geom mass="0.013" type="mesh" mesh="servo_v10_4_mesh"/>
            <body name="legMirrorDerived_v6_2">
              <joint axis="1 0 0" name="legMirrorDerived_v6_2Revolute_36" type="hinge" pos="0.0767 0.0100 -0.0365"/>
              <geom density="500" type="mesh" mesh="legMirrorDerived_v6_2_mesh"/>
              <body name="servo_v10_5">
                <geom mass="0.013" type="mesh" mesh="servo_v10_5_mesh"/>
                <body name="foorMirrorDerived_v9_1">
                  <joint axis="1 0 0" name="foorMirrorDerived_v9_1Revolute_38" type="hinge" pos="0.0767 0.0100 -0.0839"/>
                  <geom density="500" type="mesh" mesh="foorMirrorDerived_v9_1_mesh" contype="1" conaffinity="1"  friction="1.5 0.1 0.001" solref="0.02 1" />
                </body>
              </body>
            </body>
          </body>
        </body>
      </body>
    </body>
    <camera name="track" mode="trackcom" pos="0 -2.1 0.5" xyaxes="1 0 0 0 0.2 1" target="body"/>
  </worldbody>
</mujoco>
